Traceback (most recent call last):
  File "/usr/local/lib/python3.10/dist-packages/jupyter_cache/executors/utils.py", line 58, in single_nb_execution
    executenb(
  File "/usr/local/lib/python3.10/dist-packages/nbclient/client.py", line 1256, in execute
    return NotebookClient(nb=nb, resources=resources, km=km, **kwargs).execute()
  File "/usr/local/lib/python3.10/dist-packages/nbclient/util.py", line 87, in wrapped
    return just_run(coro(*args, **kwargs))
  File "/usr/local/lib/python3.10/dist-packages/nbclient/util.py", line 62, in just_run
    return loop.run_until_complete(coro)
  File "/usr/lib/python3.10/asyncio/base_events.py", line 649, in run_until_complete
    return future.result()
  File "/usr/local/lib/python3.10/dist-packages/nbclient/client.py", line 694, in async_execute
    await self.async_execute_cell(
  File "/usr/local/lib/python3.10/dist-packages/nbclient/client.py", line 1012, in async_execute_cell
    await self._check_raise_for_error(cell, cell_index, exec_reply)
  File "/usr/local/lib/python3.10/dist-packages/nbclient/client.py", line 906, in _check_raise_for_error
    raise CellExecutionError.from_cell_and_msg(cell, exec_reply_content)
nbclient.exceptions.CellExecutionError: An error occurred while executing the following cell:
------------------
Q = generator(G.weighted_adjacency_matrix(sparse=False))
show(Q)
------------------

[0;31m---------------------------------------------------------------------------[0m
[0;31mNameError[0m                                 Traceback (most recent call last)
Cell [0;32mIn [2], line 1[0m
[0;32m----> 1[0m Q [38;5;241m=[39m [43mgenerator[49m(G[38;5;241m.[39mweighted_adjacency_matrix(sparse[38;5;241m=[39m[38;5;28;01mFalse[39;00m))
[1;32m      2[0m show(Q)

[0;31mNameError[0m: name 'generator' is not defined
NameError: name 'generator' is not defined

