Traceback (most recent call last):
  File "/usr/local/lib/python3.10/dist-packages/jupyter_cache/executors/utils.py", line 58, in single_nb_execution
    executenb(
  File "/usr/local/lib/python3.10/dist-packages/nbclient/client.py", line 1256, in execute
    return NotebookClient(nb=nb, resources=resources, km=km, **kwargs).execute()
  File "/usr/local/lib/python3.10/dist-packages/nbclient/util.py", line 87, in wrapped
    return just_run(coro(*args, **kwargs))
  File "/usr/local/lib/python3.10/dist-packages/nbclient/util.py", line 62, in just_run
    return loop.run_until_complete(coro)
  File "/usr/lib/python3.10/asyncio/base_events.py", line 649, in run_until_complete
    return future.result()
  File "/usr/local/lib/python3.10/dist-packages/nbclient/client.py", line 694, in async_execute
    await self.async_execute_cell(
  File "/usr/local/lib/python3.10/dist-packages/nbclient/client.py", line 1012, in async_execute_cell
    await self._check_raise_for_error(cell, cell_index, exec_reply)
  File "/usr/local/lib/python3.10/dist-packages/nbclient/client.py", line 906, in _check_raise_for_error
    raise CellExecutionError.from_cell_and_msg(cell, exec_reply_content)
nbclient.exceptions.CellExecutionError: An error occurred while executing the following cell:
------------------
A = G.weighted_adjacency_matrix()
print(A)
------------------

[0;31m---------------------------------------------------------------------------[0m
[0;31mValueError[0m                                Traceback (most recent call last)
Cell [0;32mIn [3], line 1[0m
[0;32m----> 1[0m A [38;5;241m=[39m [43mG[49m[38;5;241;43m.[39;49m[43mweighted_adjacency_matrix[49m[43m([49m[43m)[49m
[1;32m      2[0m [38;5;28mprint[39m(A)

File [0;32m/ext/sage/10.0/src/sage/graphs/generic_graph.py:2544[0m, in [0;36mGenericGraph.weighted_adjacency_matrix[0;34m(self, sparse, vertices, default_weight, base_ring, **kwds)[0m
[1;32m   2542[0m         i [38;5;241m=[39m new_indices[u]
[1;32m   2543[0m         j [38;5;241m=[39m new_indices[v]
[0;32m-> 2544[0m         D[i, j] [38;5;241m=[39m [43mfunc[49m[43m([49m[43mu[49m[43m,[49m[43m [49m[43mv[49m[43m,[49m[43m [49m[43mlabel[49m[43m)[49m
[1;32m   2545[0m [38;5;28;01melse[39;00m:
[1;32m   2546[0m     [38;5;28;01mfor[39;00m u, v, label [38;5;129;01min[39;00m [38;5;28mself[39m[38;5;241m.[39medge_iterator():

File [0;32m/ext/sage/10.0/src/sage/graphs/generic_graph.py:2528[0m, in [0;36mGenericGraph.weighted_adjacency_matrix.<locals>.func[0;34m(u, v, label)[0m
[1;32m   2526[0m [38;5;28;01mdef[39;00m [38;5;21mfunc[39m(u, v, label):
[1;32m   2527[0m     [38;5;28;01mif[39;00m label [38;5;129;01mis[39;00m [38;5;28;01mNone[39;00m:
[0;32m-> 2528[0m         [38;5;28;01mraise[39;00m [38;5;167;01mValueError[39;00m([38;5;124mf[39m[38;5;124m"[39m[38;5;124mcannot find the weight of ([39m[38;5;132;01m{[39;00mu[38;5;132;01m}[39;00m[38;5;124m, [39m[38;5;132;01m{[39;00mv[38;5;132;01m}[39;00m[38;5;124m, None). [39m[38;5;124m"[39m
[1;32m   2529[0m                          [38;5;124m"[39m[38;5;124mConsider setting parameter [39m[38;5;124m'[39m[38;5;124mdefault_weight[39m[38;5;124m'[39m[38;5;124m"[39m)
[1;32m   2530[0m     [38;5;28;01mreturn[39;00m label

[0;31mValueError[0m: cannot find the weight of (0, 1, None). Consider setting parameter 'default_weight'
ValueError: cannot find the weight of (0, 1, None). Consider setting parameter 'default_weight'

