Traceback (most recent call last):
  File "/usr/local/lib/python3.10/dist-packages/jupyter_cache/executors/utils.py", line 58, in single_nb_execution
    executenb(
  File "/usr/local/lib/python3.10/dist-packages/nbclient/client.py", line 1256, in execute
    return NotebookClient(nb=nb, resources=resources, km=km, **kwargs).execute()
  File "/usr/local/lib/python3.10/dist-packages/nbclient/util.py", line 87, in wrapped
    return just_run(coro(*args, **kwargs))
  File "/usr/local/lib/python3.10/dist-packages/nbclient/util.py", line 62, in just_run
    return loop.run_until_complete(coro)
  File "/usr/lib/python3.10/asyncio/base_events.py", line 649, in run_until_complete
    return future.result()
  File "/usr/local/lib/python3.10/dist-packages/nbclient/client.py", line 694, in async_execute
    await self.async_execute_cell(
  File "/usr/local/lib/python3.10/dist-packages/nbclient/client.py", line 1012, in async_execute_cell
    await self._check_raise_for_error(cell, cell_index, exec_reply)
  File "/usr/local/lib/python3.10/dist-packages/nbclient/client.py", line 906, in _check_raise_for_error
    raise CellExecutionError.from_cell_and_msg(cell, exec_reply_content)
nbclient.exceptions.CellExecutionError: An error occurred while executing the following cell:
------------------
var('a12, a21, a13, a31, a23, a32, a34, a43')
d = {1: {2:a12, 3:a13}, 2: {1:a21, 3:a23}, 3: {2:a32, 1:a31, 4:a34}, 4: {3:a43}};
G = DiGraph(d,weighted=True)
G.plot(figsize=8,edge_labels=True,pos=vertex_positions,graph_border=True)
------------------

[0;31m---------------------------------------------------------------------------[0m
[0;31mNameError[0m                                 Traceback (most recent call last)
Cell [0;32mIn [1], line 4[0m
[1;32m      2[0m d [38;5;241m=[39m {Integer([38;5;241m1[39m): {Integer([38;5;241m2[39m):a12, Integer([38;5;241m3[39m):a13}, Integer([38;5;241m2[39m): {Integer([38;5;241m1[39m):a21, Integer([38;5;241m3[39m):a23}, Integer([38;5;241m3[39m): {Integer([38;5;241m2[39m):a32, Integer([38;5;241m1[39m):a31, Integer([38;5;241m4[39m):a34}, Integer([38;5;241m4[39m): {Integer([38;5;241m3[39m):a43}};
[1;32m      3[0m G [38;5;241m=[39m DiGraph(d,weighted[38;5;241m=[39m[38;5;28;01mTrue[39;00m)
[0;32m----> 4[0m G[38;5;241m.[39mplot(figsize[38;5;241m=[39mInteger([38;5;241m8[39m),edge_labels[38;5;241m=[39m[38;5;28;01mTrue[39;00m,pos[38;5;241m=[39m[43mvertex_positions[49m,graph_border[38;5;241m=[39m[38;5;28;01mTrue[39;00m)

[0;31mNameError[0m: name 'vertex_positions' is not defined
NameError: name 'vertex_positions' is not defined

